#VRML_SIM R2023a utf8

EXTERNPROTO "https://raw.githubusercontent.com/cyberbotics/webots/R2022b/projects/objects/floors/protos/Floor.proto"

WorldInfo {
}
Viewpoint {
  orientation -0.09667227224551193 0.9138493667746839 0.39437774610695125 0.5241606940625919
  position -1.4226467340486937 -0.4442985010784768 1.2325805151799436
}
Background {
  skyColor [
    1 0.988235 0.992157
  ]
}
DirectionalLight {
}
Floor {
}
Robot {
  translation 0 0 0.5
  rotation 0 1 0 0
  children [
    DEF BODY_GEO Shape {
      appearance PBRAppearance {
        baseColor 1 0.682353 0.0470588
        roughness 1
        metalness 0
      }
      geometry Box {
        size 0.3 0.1 0.1
      }
    }
    HingeJoint {
      jointParameters HingeJointParameters {
        position 4.1240736230700326e-07
        axis 0 0 -1
        anchor 0 -0.05 0
      }
      device [
        RotationalMotor {
          name "joint1"
          minPosition -1.5708
          maxPosition 1.5708
        }
      ]
      endPoint DEF JOINT1 Solid {
        translation 0 -0.05 0
        rotation 0.9999999999999787 -2.0726705690590305e-07 -9.602018440956093e-12 3.1415
        children [
          Shape {
            appearance PBRAppearance {
              baseColor 1 0 0
              roughness 1
              metalness 0
            }
            geometry DEF LINK1_GEO Cylinder {
              height 0.05
              radius 0.02
            }
          }
          HingeJoint {
            jointParameters HingeJointParameters {
              position 2.548410069636611e-07
            }
            device [
              RotationalMotor {
                name "joint2"
                minPosition -1.5708
                maxPosition 1.5708
              }
            ]
            endPoint Solid {
              translation 0 0.0749999999999972 1.911307552227428e-08
              rotation -1 4.9624424136713204e-14 1.1156566611707874e-13 -1.5708002548409805
              children [
                Shape {
                  appearance PBRAppearance {
                    baseColor 1 0 0
                    roughness 1
                    metalness 0
                  }
                  geometry DEF LINK2_GEO Cylinder {
                    height 0.15
                    radius 0.015
                  }
                }
                HingeJoint {
                  jointParameters HingeJointParameters {
                    position 7.808111178846011e-12
                    anchor 0 0 -0.075
                  }
                  device [
                    RotationalMotor {
                      name "joint3"
                      minPosition -1.5708
                      maxPosition 1.5708
                    }
                  ]
                  endPoint Solid {
                    translation 0 0.075 -0.07499999999941438
                    rotation 1 -3.1273011935775813e-14 -3.066790376226516e-14 1.5708000000078084
                    children [
                      Shape {
                        appearance PBRAppearance {
                          baseColor 0 0 0.498039
                          roughness 1
                          metalness 0
                        }
                        geometry DEF LINK3_GEO Capsule {
                          height 0.15
                          radius 0.015
                        }
                      }
                    ]
                    boundingObject USE LINK3_GEO
                    physics Physics {
                    }
                    linearVelocity -6.190676300893815e-07 2.382520673306923e-10 -7.76214579738418e-08
                    angularVelocity 3.177879227448355e-09 -9.745768062783332e-12 -4.128275992886768e-06
                  }
                }
              ]
              name "link2"
              boundingObject DEF LINK2_GEO Cylinder {
                height 0.15
                radius 0.015
              }
              physics Physics {
              }
              linearVelocity -3.0947193254198213e-07 -5.255204430583326e-14 -6.279374970932542e-08
              angularVelocity 3.1778763295815403e-09 -5.874362089140043e-12 -4.128276031041814e-06
            }
          }
        ]
        name "link1"
        boundingObject USE LINK1_GEO
        physics Physics {
        }
        linearVelocity 7.438263585105802e-11 -1.526952032172723e-14 -3.509246308958336e-08
        angularVelocity 3.154101644416688e-09 -2.0038638549695708e-12 -4.128286106034693e-06
      }
    }
  ]
  name "KinLeg"
  boundingObject USE BODY_GEO
  controller "kin_leg_controller"
  supervisor TRUE
}
DEF BALL Solid {
  translation -0.153245 -0.276837 0.45
  children [
    Shape {
      appearance PBRAppearance {
        baseColor 0 1 0
        roughness 1
        metalness 0
      }
      geometry Sphere {
        radius 0.02
        subdivision 3
      }
    }
  ]
  name "target"
}
